#VRML_SIM R2022a utf8
WorldInfo {
}
Viewpoint {
  orientation 0.1383668002907735 0.8878281821573955 -0.4388801061159959 0.6824108724701837
  position -1.8543778804694455 0.6422323540585942 1.7219390888153638
}
TexturedBackground {
}
TexturedBackgroundLight {
}
RectangleArena {
}
DEF ROBOT Robot {
  translation 2.70688e-08 0.0475879 0.0392
  rotation -1 -2.79948e-07 2.55017e-07 -1.4902253071795863
  children [
    DEF EMITTER Emitter {
    }
    DEF RECEIVER Receiver {
    }
    DEF HINGE_COVER Solid {
      translation 0 0.03 -3.469446951953614e-18
      children [
        Shape {
          appearance PBRAppearance {
            baseColor 0 0.6509803921568628 1
          }
          geometry Box {
            size 0.030000000000000002 0.019999999999999997 0.05
          }
        }
      ]
      name "hingeCover"
    }
    DEF BODY Shape {
      appearance PBRAppearance {
        baseColor 0.917647 0.145098 0.145098
        roughness 1
        metalness 0
      }
      geometry Box {
        size 0.1 0.05 0.2
      }
    }
    DEF WHEEL1 HingeJoint {
      jointParameters HingeJointParameters {
        position 1.1199999978392188
        anchor 0.06 0 0.05
      }
      device [
        RotationalMotor {
          name "wheel1"
        }
      ]
      endPoint Solid {
        translation 0.06 0 0.05
        rotation 0.6979908652019232 0.16004596909144528 0.6979928652015369 2.82419
        children [
          DEF WHEEL Shape {
            appearance PBRAppearance {
              baseColor 0.305882 0.898039 0.25098
              roughness 1
              metalness 0
            }
            geometry Cylinder {
              height 0.02
              radius 0.04
              subdivision 24
            }
          }
        ]
        boundingObject USE WHEEL
        physics Physics {
        }
      }
    }
    DEF WHEEL2 HingeJoint {
      jointParameters HingeJointParameters {
        position 1.119999997840028
        anchor -0.06 0 0.05
      }
      device [
        RotationalMotor {
          name "wheel2"
        }
      ]
      endPoint Solid {
        translation -0.06 0 0.05
        rotation 0.21811292034419452 0.9512376526037921 -0.21811392034382932 -1.6207753071795858
        children [
          USE WHEEL
        ]
        name "solid(1)"
        boundingObject USE WHEEL
        physics Physics {
        }
      }
    }
    DEF WHEEL3 HingeJoint {
      jointParameters HingeJointParameters {
        position 1.1377780362717862
        anchor 0.06 0 -0.05
      }
      device [
        RotationalMotor {
          name "wheel3"
        }
      ]
      endPoint Solid {
        translation 0.06 0 -0.05
        rotation 0.6987047814752229 0.153684951933963 0.6987077814742846 2.83661
        children [
          USE WHEEL
        ]
        name "solid(2)"
        boundingObject USE WHEEL
        physics Physics {
        }
      }
    }
    DEF WHEEL4 HingeJoint {
      jointParameters HingeJointParameters {
        position 1.1377778166381554
        anchor -0.06 0 -0.05
      }
      device [
        RotationalMotor {
          name "wheel4"
        }
      ]
      endPoint Solid {
        translation -0.06 0 -0.05
        rotation 0.21002904317126422 0.9548691962724285 -0.21003004317146975 -1.6169653071795862
        children [
          USE WHEEL
        ]
        name "solid(3)"
        boundingObject USE WHEEL
        physics Physics {
        }
      }
    }
    DEF POLE HingeJoint {
      jointParameters HingeJointParameters {
        position -0.009827678820998286
        anchor 0 0.03000000000047226 0
        minStop -1.3
        maxStop 1.3
      }
      device [
        DEF POLE_POS_SENSOR PositionSensor {
          name "polePosSensor"
        }
      ]
      endPoint Solid {
        translation -1.8379558561220526e-06 0.5299727419373773 -0.004913729722725189
        rotation -0.004913742247791086 0.004913760313636146 0.9999758547568548 1.5708241489187766
        children [
          DEF POLE_ENDPOINT Solid {
            translation 0.5000000000000002 0 0
            scale 0.1 0.1 0.1
            children [
              DEF BALL Shape {
                appearance PBRAppearance {
                  baseColor 0.03137254901960784 0.047058823529411764 1
                  metalness 0
                }
                geometry Sphere {
                  radius 0.1
                }
              }
            ]
            boundingObject USE BALL
            physics Physics {
              density -1
              mass 0.02
            }
          }
          DEF POLE Shape {
            appearance PBRAppearance {
              baseColor 1 0.1568627450980392 0.1568627450980392
              roughness 1
              metalness 0
            }
            geometry Box {
              size 1 0.020000000000000004 0.019999999999999997
            }
          }
        ]
        name "pole"
        boundingObject USE POLE
        physics Physics {
          density -1
          mass 0.2
        }
      }
    }
  ]
  name "robot(1)"
  boundingObject USE BODY
  physics Physics {
    density -1
    mass 2
  }
  controller "robotController"
}
Robot {
  children [
    Emitter {
    }
    Receiver {
    }
  ]
  controller "supervisorController"
  supervisor TRUE
}
